Workbook

Sheet MOIS COMP
A2: Exp | B2: 45992 | C2: 45993 | D2: 45994 | E2: 45995 | F2: 45996 | G2: 45997 | H2: 45998 | I2: 45999 | J2: 46000 | K2: 46001 | L2: 46002 | M2: 46003 | N2: 46004 | O2: 46005 | P2: 46006 | Q2: 46007 | R2: 46008 | S2: 46009 | T2: 46010 | U2: 46011 | V2: 46012 | W2: 46013 | X2: 46014 | Y2: 46015 | Z2: 46016 | AA2: 46017 | AB2: 46018 | AC2: 46019 | AD2: 46020 | AE2: 46021 | AF2: 46022 | AG2: Total général
A3: 14 | B3: 1036 | C3: 2000 | K3: 2495.1 | AG3: =SUM(B3:AF3) -> 5531.1
A4: 15 | B4: 4815 | C4: 1600 | D4: 20498.8 | E4: 5656 | F4: 4325.6 | J4: 2191 | L4: 1421 | AG4: =SUM(B4:AF4) -> 40507.4
A5: 16 | B5: 1257.3 | F5: 296 | G5: 2354 | H5: 5022 | K5: 302 | L5: 200 | AG5: =SUM(B5:AF5) -> 9431.3
A6: 17 | B6: 4119.9 | C6: 987 | D6: 1000 | E6: 3790 | F6: 1222 | I6: 3147.9 | J6: 5000 | K6: 4843 | L6: 965 | M6: 2387 | AG6: =SUM(B6:AF6) -> 27461.8
A7: 18 | B7: 430.19 | C7: 1171 | E7: 991 | F7: 893 | G7: 4538 | H7: 10052 | I7: 5030.9 | J7: 671 | L7: 133 | M7: 1474 | AG7: =SUM(B7:AF7) -> 25384.09
A8: 19 | C8: 363 | D8: 9230 | AG8: =SUM(B8:AF8) -> 9593
A9: 20 | B9: 1000 | L9: 781.6 | AG9: =SUM(B9:AF9) -> 1781.6
A10: 23 | B10: 10863 | C10: 13549.3 | D10: 16103 | E10: 19551 | F10: 13056.3 | G10: 2493.6 | H10: 3321 | I10: 11629 | J10: 17325 | K10: 10527.69 | L10: 11506.4 | M10: 5321 | AG10: =SUM(B10:AF10) -> 135246.29
A11: 24 | F11: 1170 | I11: 541 | AG11: =SUM(B11:AF11) -> 1711
A12: 25 | B12: 8276.7 | C12: 2067.2 | D12: 3831.59 | E12: 2086.3 | F12: 9042.5 | G12: 1125 | I12: 22000.5 | J12: 406 | K12: 3630 | L12: 10773.7 | M12: 7812.8 | AG12: =SUM(B12:AF12) -> 71052.29
A13: 26 | E13: 196.9 | M13: 1377 | AG13: =SUM(B13:AF13) -> 1573.9
A14: 27 | B14: 183.2 | C14: 317.39 | I14: 2664 | L14: 424 | AG14: =SUM(B14:AF14) -> 3588.59
A15: 28 | B15: 500 | C15: 217 | L15: 1759.4 | AG15: =SUM(B15:AF15) -> 2476.4
A16: 29 | B16: 293 | C16: 23026 | D16: 11509 | E16: 1307 | F16: 735 | I16: 10100 | J16: 12400 | K16: 400 | M16: 600 | AG16: =SUM(B16:AF16) -> 60370
A17: 30 | E17: 2860.5 | F17: 6051 | AG17: =SUM(B17:AF17) -> 8911.5
A18: 31 | B18: 1025.8 | C18: 614 | E18: 730 | H18: 273 | L18: 724 | M18: 500 | AG18: =SUM(B18:AF18) -> 3866.8
A19: 32 | B19: 1198 | D19: 1575 | I19: 174 | L19: 1000 | AG19: =SUM(B19:AF19) -> 3947
A20: 33 | B20: 3499.4 | G20: 750 | I20: 1002 | J20: 100 | K20: 100 | L20: 1862 | M20: 307.7 | AG20: =SUM(B20:AF20) -> 7621.1
A21: 34 | C21: 141 | D21: 125 | I21: 2336.8 | K21: 544 | M21: 678.8 | AG21: =SUM(B21:AF21) -> 3825.6
A22: 35 | C22: 4695 | D22: 2960 | E22: 9273 | F22: 20610 | G22: 36720 | I22: 13800 | J22: 4100 | L22: 35797 | M22: 303 | AG22: =SUM(B22:AF22) -> 128258
A23: 36 | D23: 584 | E23: 428 | G23: 1938 | H23: 15923.5 | I23: 2142 | J23: 7723 | K23: 1198 | L23: 1856 | M23: 535 | AG23: =SUM(B23:AF23) -> 32327.5
A24: 37 | B24: 198 | E24: 1000 | F24: 500 | K24: 14363 | L24: 8264 | M24: 1404 | AG24: =SUM(B24:AF24) -> 25729
A25: 39 | B25: 54008.09 | C25: 44688 | D25: 46913.7 | E25: 32954 | F25: 11137.6 | G25: 5463 | H25: 1702 | I25: 30403.7 | J25: 32510 | K25: 30257.2 | L25: 27011.8 | M25: 11654.3 | AG25: =SUM(B25:AF25) -> 328703.39
A26: 40 | B26: 44852.5 | C26: 33723 | D26: 23170.36 | E26: 55803.4 | F26: 28207.98 | G26: 16128.5 | H26: 13874.2 | I26: 90446.97 | J26: 75275.6 | K26: 75729.4 | L26: 62654.29 | M26: 47044.4 | AG26: =SUM(B26:AF26) -> 566910.6
A27: 41 | B27: 81609.6 | C27: 66474.4 | D27: 71556 | E27: 61616.6 | F27: 102280.8 | G27: 6725 | H27: 8825.8 | I27: 97992.9 | J27: 207612.8 | K27: 129626.7 | L27: 58766.5 | M27: 55782.5 | AG27: =SUM(B27:AF27) -> 948869.6
A28: 42 | B28: 91514.4 | C28: 86031 | D28: 69375.6 | E28: 44816.1 | F28: 36534.39 | G28: 11032.9 | H28: 6795.6 | I28: 84275.5 | J28: 49086.7 | K28: 41206 | L28: 53665.6 | M28: 53915.2 | AG28: =SUM(B28:AF28) -> 628248.99
A29: 43 | B29: 142751.59 | C29: 104077.4 | D29: 106950.9 | E29: 87164 | F29: 72021.6 | G29: 57632 | H29: 22051.5 | I29: 169162.7 | J29: 242951.7 | K29: 394061.6 | L29: 164805.5 | M29: 132467.29 | AG29: =SUM(B29:AF29) -> 1696097.8
A30: 44 | B30: 75910.39 | C30: 43825.8 | D30: 23165.1 | E30: 36766.49 | F30: 54212 | G30: 9511 | H30: 9101 | I30: 74858.2 | J30: 95296.28 | K30: 77019.29 | L30: 51745.4 | M30: 56084.3 | AG30: =SUM(B30:AF30) -> 607495.25
A31: 45 | B31: 97437.3 | C31: 69688 | D31: 54593.9 | E31: 38820.2 | F31: 78960 | G31: 25943.4 | H31: 20608.1 | I31: 56208.2 | J31: 92992.5 | K31: 66369.7 | L31: 48507.4 | M31: 59727.4 | AG31: =SUM(B31:AF31) -> 709856.1
A32: 46 | B32: 72841.89 | C32: 49297.5 | D32: 25605.6 | E32: 36980.89 | F32: 36236.9 | G32: 7624.8 | H32: 3156.1 | I32: 55652.89 | J32: 48804.29 | K32: 64214.7 | L32: 74514.49 | M32: 41536.8 | AG32: =SUM(B32:AF32) -> 516466.85
A33: 47 | B33: 82418.9 | C33: 60409.4 | D33: 78182.9 | E33: 37709.6 | F33: 68684.2 | G33: 30560 | H33: 14702.2 | I33: 91976.5 | J33: 53854.2 | K33: 78613.6 | L33: 101538.71 | M33: 72248.48 | AG33: =SUM(B33:AF33) -> 770898.69
A34: 48 | B34: 97727.39 | C34: 58430.3 | D34: 39555.9 | E34: 39325.79 | F34: 24416.9 | G34: 10319.4 | H34: 5227 | I34: 56505.3 | J34: 35781 | K34: 115472.1 | L34: 87766.7 | M34: 115476.6 | AG34: =SUM(B34:AF34) -> 686004.38
A35: 49 | B35: 50221.09 | C35: 29575.79 | D35: 21316.6 | E35: 23530.2 | F35: 24639.09 | G35: 43450 | H35: 5632 | I35: 65642.5 | J35: 52791.1 | K35: 63063.5 | L35: 67646.59 | M35: 62963.39 | AG35: =SUM(B35:AF35) -> 510471.85
A36: 50 | B36: 35403.3 | C36: 27884 | D36: 28669.5 | E36: 20286.5 | F36: 16532.5 | G36: 1236 | H36: 3107 | I36: 23405.5 | J36: 23637.1 | K36: 34872.3 | L36: 180103.39 | M36: 27353.6 | AG36: =SUM(B36:AF36) -> 422490.69
... A41: 60 | B41: 91002.19 | C41: 27485.3 | D41: 54997.49 | E41: 81206.7 | F41: 27036.5 | G41: 7299 | H41: 7148.4 | I41: 36351.5 | J41: 205107.89 | K41: 81580.7 | L41: 141355.19 | M41: 43035.9 | AG41: =SUM(B41:AF41) -> 803606.76
A42: 61 | B42: 35541.46 | C42: 14483.3 | D42: 14943 | E42: 16622.4 | F42: 5066.5 | G42: 803 | I42: 8630.6 | J42: 21038.1 | K42: 4672.9 | L42: 11275.1 | M42: 2414 | AG42: =SUM(B42:AF42) -> 135490.36
A43: 62 | B43: 2049 | D43: 1378 | H43: 195 | I43: 4851 | J43: 547 | K43: 835.4 | M43: 1528.6 | AG43: =SUM(B43:AF43) -> 11384
A44: 64 | B44: 37283.39 | C44: 46202.6 | D44: 69968.39 | E44: 24422.9 | F44: 32144.8 | G44: 4372 | H44: 6305.5 | I44: 36414.6 | J44: 62982 | K44: 49592.5 | L44: 44625.8 | M44: 24236.1 | AG44: =SUM(B44:AF44) -> 438550.58
A45: 65 | B45: 18776 | C45: 27697.8 | D45: 14742.6 | E45: 25148.6 | F45: 10464.8 | G45: 18067.6 | H45: 10436.2 | I45: 103968.48 | J45: 97125.9 | K45: 93222.07 | L45: 96107.7 | M45: 97713.4 | AG45: =SUM(B45:AF45) -> 613471.15
...

Sheet BASE 
A1: DEP | B1: EXP | C1: 46113 | D1: 46114 | E1: 46115 | F1: 46116 | G1: 46117 | H1: 46118 | I1: 46119 | J1: 46120 | K1: 46121 | L1: 46122 | M1: 46123 | N1: 46124 | O1: 46125 | P1: 46126 | Q1: 46127 | R1: 46128 | S1: 46129 | T1: 46130 | U1: 46131 | V1: 46132 | W1: 46133 | X1: 46134 | Y1: 46135 | Z1: 46136 | AA1: 46137 | AB1: 46138 | AC1: 46139 | AD1: 46140 | AE1: 46141 | AF1: 46142 | AH1: Total EXP
A2: NKTT | B2: 14 | C2: 2035 | D2: 5075 | H2: 250 | I2: 1170 | K2: 5084 | AH2: =SUM(C2:AG2) -> 13614
A3: NKTT | B3: 15 | C3: 500 | E3: 274 | H3: 3000 | L3: 2035 | M3: 1500 | AH3: =SUM(C3:AG3) -> 7309
A4: NKTT | B4: 16 | C4: 214 | D4: 671 | E4: 3033.4 | F4: 2656 | I4: 1000 | J4: 1447.6 | K4: 5909.3 | AH4: =SUM(C4:AG4) -> 14931.3
A5: NKTT | B5: 17 | C5: 1554 | D5: 576 | E5: 4155.5 | F5: 1121.9 | G5: 1252 | H5: 473 | I5: 2892 | J5: 1427 | K5: 1765.5 | L5: 2561 | M5: 627 | N5: 456 | AH5: =SUM(C5:AG5) -> 18860.9
A6: NKTT | B6: 18 | C6: 101 | E6: 22 | G6: 329 | L6: 644 | M6: 40 | N6: 610 | AH6: =SUM(C6:AG6) -> 1746
A7: NKTT | B7: 19 | H7: 500 | I7: 3211 | J7: 1690 | M7: 125 | AH7: =SUM(C7:AG7) -> 5526
A8: NKTT | B8: 20 | I8: 485.2 | J8: 123 | AH8: =SUM(C8:AG8) -> 608.2
A9: NKTT | B9: 21 | F9: 1393 | J9: 100 | AH9: =SUM(C9:AG9) -> 1493
A10: NKTT | B10: 23 | C10: 19264 | D10: 25785.4 | E10: 6761 | F10: 5064 | G10: 4831.4 | H10: 20071 | I10: 12227 | J10: 14294.1 | K10: 16926 | L10: 6308 | M10: 13725.4 | N10: 31386 | AH10: =SUM(C10:AG10) -> 176643.3
A11: NKTT | B11: 24 | D11: 415 | H11: 4800 | M11: 6844.4 | AH11: =SUM(C11:AG11) -> 12059.4
A12: NKTT | B12: 25 | C12: 1554.4 | D12: 4394.59 | E12: 5879.29 | F12: 1083 | G12: 1580 | H12: 933 | I12: 6909.79 | J12: 545 | K12: 3373.1 | L12: 1434 | M12: 23390 | N12: 250 | AH12: =SUM(C12:AG12) -> 51326.17
A13: NKTT | B13: 26 | C13: 638.7 | G13: 1800 | H13: 182 | I13: 400 | AH13: =SUM(C13:AG13) -> 3020.7
A14: NKTT | B14: 27 | I14: 870 | J14: 1123 | K14: 2581 | AH14: =SUM(C14:AG14) -> 4574
A15: NKTT | B15: 28 | C15: 895 | H15: 2542 | I15: 1749.9 | J15: 1813 | M15: 822 | AH15: =SUM(C15:AG15) -> 7821.9
A16: NKTT | B16: 29 | C16: 64727.7 | D16: 29630 | E16: 17006.2 | F16: 1040 | G16: 2005 | H16: 15975 | I16: 570 | J16: 2866 | K16: 3357 | L16: 700 | M16: 542 | AH16: =SUM(C16:AG16) -> 138418.9
A17: NKTT | B17: 30 | C17: 300 | J17: 357 | M17: 465 | N17: 859 | AH17: =SUM(C17:AG17) -> 1981
A18: NKTT | B18: 31 | D18: 106 | E18: 844 | I18: 2563 | AH18: =SUM(C18:AG18) -> 3513
A19: NKTT | B19: 32 | C19: 2014 | D19: 1639 | F19: 692 | G19: 1772.9 | I19: 1013.8 | K19: 550 | L19: 234 | M19: 270 | N19: 600 | AH19: =SUM(C19:AG19) -> 8785.7
A20: NKTT | B20: 33 | C20: 500 | D20: 4783.3 | E20: 800 | F20: 1030 | H20: 555 | I20: 737 | J20: 5215 | L20: 1192 | M20: 543 | AH20: =SUM(C20:AG20) -> 15355.3
A21: NKTT | B21: 34 | C21: 1280 | D21: 7298 | E21: 222 | F21: 200 | G21: 230 | H21: 15610 | I21: 10221.7 | J21: 5886 | K21: 5890 | L21: 3500 | M21: 146 | N21: 20170 | AH21: =SUM(C21:AG21) -> 70653.7
A22: NKTT | B22: 35 | C22: 22178 | D22: 14367 | E22: 14330 | F22: 14929 | H22: 15595 | I22: 6240.5 | J22: 1880 | L22: 6950 | M22: 2033 | N22: 800 | AH22: =SUM(C22:AG22) -> 99302.5
A23: NKTT | B23: 36 | C23: 108 | E23: 2534 | F23: 191 | G23: 3734 | H23: 1986 | I23: 1538.2 | J23: 1817 | K23: 1149.1 | L23: 2099 | M23: 1791 | N23: 1804.1 | AH23: =SUM(C23:AG23) -> 18751.4
A24: NKTT | B24: 37 | C24: 7100 | D24: 5880 | E24: 500 | F24: 3300 | H24: 21314 | I24: 19159 | J24: 12238 | K24: 17090 | L24: 5700 | M24: 2815 | AH24: =SUM(C24:AG24) -> 95096
A25: NKTT | B25: 39 | C25: 36932 | D25: 37991.6 | E25: 4445.5 | F25: 11287 | H25: 24889 | I25: 36008 | J25: 32117.7 | K25: 24612.6 | L25: 25073.4 | M25: 23450 | N25: 5475 | AH25: =SUM(C25:AG25) -> 262281.8
A26: NKTT | B26: 40 | C26: 37481.6 | D26: 39042 | E26: 30402.6 | F26: 15180.4 | G26: 16721.6 | H26: 82394.3 | I26: 71350.17 | J26: 81210.19 | K26: 99438.1 | L26: 43533.1 | M26: 29107 | N26: 26571.8 | AH26: =SUM(C26:AG26) -> 572432.86
A27: NKTT | B27: 41 | C27: 104814.9 | D27: 54877 | E27: 41779.7 | F27: 48396 | G27: 5640.2 | H27: 91234.2 | I27: 307198.49 | J27: 129172.1 | K27: 105568.8 | L27: 76647.5 | M27: 63910.3 | N27: 20588.4 | AH27: =SUM(C27:AG27) -> 1049827.6
A28: NDB | B28: 42 | C28: 33038.5 | D28: 23759.1 | E28: 29204.2 | F28: 19281.6 | G28: 9317.9 | H28: 68855.3 | I28: 93989.5 | J28: 64963.8 | K28: 83322.3 | L28: 70768.8 | M28: 30157.7 | N28: 9421.7 | AH28: =SUM(C28:AG28) -> 536080.4
A29: NDB | B29: 43 | C29: 223702.9 | D29: 195744.7 | E29: 189971.5 | F29: 19704 | G29: 12824.9 | H29: 193188.1 | I29: 115971.9 | J29: 100794.8 | K29: 76808.4 | L29: 134843 | M29: 72053.3 | N29: 61894.2 | AH29: =SUM(C29:AG29) -> 1397501.7
A30: NDB | B30: 44 | C30: 35630.5 | D30: 41046.4 | E30: 42609.5 | F30: 12300 | G30: 11525 | H30: 63611.9 | I30: 39809.4 | J30: 60996.7 | K30: 48801.2 | L30: 33169.4 | M30: 20494.7 | N30: 14047.6 | AH30: =SUM(C30:AG30) -> 424042.3
A31: NDB | B31: 45 | C31: 47754.4 | D31: 59191 | E31: 38328.4 | F31: 13748.6 | G31: 8990 | H31: 60551.1 | I31: 26087.2 | J31: 55069.8 | K31: 61307.59 | L31: 24383 | M31: 25310 | N31: 9901.9 | AH31: =SUM(C31:AG31) -> 430622.99
A32: INT | B32: 46 | C32: 33343.5 | D32: 42884.6 | E32: 25954.2 | F32: 11617 | G32: 3734 | H32: 41577.9 | I32: 34371.1 | J32: 19437.79 | K32: 59476.9 | L32: 16146 | M32: 30146.9 | N32: 16839.9 | AH32: =SUM(C32:AG32) -> 335529.79
A33: INT | B33: 47 | C33: 38263.5 | D33: 55232.4 | E33: 34366.6 | F33: 22520.3 | G33: 15047.9 | H33: 89654.1 | I33: 82149.09 | J33: 132870.7 | K33: 127741.4 | L33: 86357 | M33: 74239.1 | N33: 31523.5 | AH33: =SUM(C33:AG33) -> 789965.59
A34: INT | B34: 48 | C34: 31629.6 | D34: 68799.5 | E34: 20638.8 | F34: 7886.4 | G34: 7443 | H34: 48492.9 | I34: 63471.5 | J34: 43246.6 | K34: 62849.9 | L34: 49405.4 | M34: 47532.1 | N34: 17021.8 | AH34: =SUM(C34:AG34) -> 468417.5
A35: INT | B35: 49 | C35: 26061.3 | D35: 38423 | E35: 33208.1 | F35: 9631 | G35: 5030 | H35: 59559.4 | I35: 50697.8 | J35: 20327.2 | K35: 89586.7 | L35: 42330.1 | M35: 33472.3 | N35: 11670.2 | AH35: =SUM(C35:AG35) -> 419997.1
A36: INT | B36: 50 | C36: 24765.5 | D36: 21085.3 | E36: 12094 | F36: 6249 | G36: 3198 | H36: 36252 | I36: 23054.6 | J36: 32378.2 | K36: 36060.99 | L36: 33766.5 | M36: 38611 | N36: 4921 | AH36: =SUM(C36:AG36) -> 272436.09
A37: INT | B37: 51 | C37: 25671.69 | D37: 25073 | E37: 7345 | F37: 4328 | G37: 2571.9 | H37: 42520 | I37: 32544.8 | J37: 51656.8 | K37: 32973.4 | L37: 22212.3 | M37: 14141.3 | N37: 7555.4 | AH37: =SUM(C37:AG37) -> 268593.59
... A42: INT | B42: 61 | C42: 15797.2 | D42: 15790 | E42: 2836.8 | F42: 896 | G42: 1332 | H42: 6375 | I42: 15854.5 | J42: 9602 | K42: 29781 | L42: 2962 | M42: 2398.5 | N42: 2446 | AH42: =SUM(C42:AG42) -> 106071
A43: INT | B43: 62 | C43: 2810 | D43: 739.3 | E43: 13232 | G43: 950 | H43: 2000 | I43: 1852.5 | J43: 770 | K43: 200 | L43: 1352 | M43: 603 | AH43: =SUM(C43:AG43) -> 24508.8
A44: INT | B44: 64 | C44: 31508.2 | D44: 59670 | E44: 23838.9 | F44: 19188 | G44: 5886.5 | H44: 41240 | I44: 57927.49 | J44: 32486.5 | K44: 124329 | L44: 6617 | M44: 2935.3 | N44: 3394.8 | AH44: =SUM(C44:AG44) -> 409021.69
...

Sheet SNDE
A1: SNDE
A2: DG
A3: SUIVI OBJECTIFS EN ENCAISSEMENTS GLOBAUX
A4: ZONE NKTT NORD
A5: EXP | B5: CENTRE | C5: OBJECTIF JDC | D5: ='BASE '!P92 -> ENCAISSEMENTS AU 12/04/2026 | E5: ECART DU MOIS | F5: %
A6: 86 | B6: WAD NAGA | C6: 1561340 | D6: =VLOOKUP(A6,'BASE '!$B$2:$AH$87,33,FALSE) -> 583133.1 | E6: =D6-C6 -> -978206.9 | F6: =D6/C6 -> 0.37348246
A7: 96 | B7: KSAR | C7: 4400000 | D7: =VLOOKUP(A7,'BASE '!$B$2:$AH$87,33,FALSE) -> 1460235.9 | E7: =D7-C7 -> -2939764.1 | F7: =D7/C7 -> 0.33187179
A8: 41 | B8: TEYARETT 2 | C8: 2530000 | D8: =VLOOKUP(A8,'BASE '!$B$2:$AH$87,33,FALSE) -> 1049827.6 | E8: =D8-C8 -> -1480172.4 | F8: =D8/C8 -> 0.41495162
A9: 52 | B9: MELLAH 3 | C9: 1810468 | D9: =VLOOKUP(A9,'BASE '!$B$2:$AH$87,33,FALSE) -> 447698.69 | E9: =D9-C9 -> -1362769.3 | F9: =D9/C9 -> 0.2472834
A10: 44 | B10: DAR NAIM-NORD | C10: 1650000 | D10: =VLOOKUP(A10,'BASE '!$B$2:$AH$87,33,FALSE) -> 424042.3 | E10: =D10-C10 -> -1225957.7 | F10: =D10/C10 -> 0.25699533
A11: 48 | B11: DAR NAIM-SUD 2 | C11: 2527668 | D11: =VLOOKUP(A11,'BASE '!$B$2:$AH$87,33,FALSE) -> 468417.5 | E11: =D11-C11 -> -2059250.5 | F11: =D11/C11 -> 0.18531607
A12: 47 | B12: TEYARETT 1 | C12: 2530000 | D12: =VLOOKUP(A12,'BASE '!$B$2:$AH$87,33,FALSE) -> 789965.59 | E12: =D12-C12 -> -1740034.4 | F12: =D12/C12 -> 0.31223936
A13: 99 | B13: DAR NAIM-SUD 1 | C13: 2389332 | D13: =VLOOKUP(A13,'BASE '!$B$2:$AH$87,33,FALSE) -> 512338.89 | E13: =D13-C13 -> -1876993.1 | F13: =D13/C13 -> 0.21442767
A14: 98 | B14: TOUJOUNINE | C14: 3300000 | D14: =VLOOKUP(A14,'BASE '!$B$2:$AH$87,33,FALSE) -> 494924.01 | E14: =D14-C14 -> -2805076 | F14: =D14/C14 -> 0.14997697
A15: TOTAL ZONE NKTT NORD | C15: =SUM(C6:C14) -> 22698808 | D15: =SUM(D6:D14) -> 6230583.5 | E15: =SUM(E6:E14) -> -16468224 | F15: =D15/C15 -> 0.27448946
A17: ENCAISSEMENTS GLOBAUX
A18: ZONE NKTT SUD
A19: EXP | B19: CENTRE | C19: OBJECTIF DC | D19: ='BASE '!P92 -> ENCAISSEMENTS AU 12/04/2026 | E19: ECART DU MOIS | F19: %
A20: 95 | B20: CARREFOUR | C20: 2566080 | D20: =VLOOKUP(A20,'BASE '!$B$2:$AH$87,33,FALSE) -> 982564.6 | E20: =D20-C20 -> -1583515.4 | F20: =D20/C20 -> 0.3829049
A21: 89 | B21: RIYAD | C21: 2403878.4 | D21: =VLOOKUP(A21,'BASE '!$B$2:$AH$87,33,FALSE) -> 740798.56 | E21: =D21-C21 -> -1663079.8 | F21: =D21/C21 -> 0.30816807
A22: 53 | B22: RIYADH 2 | C22: 1946670 | D22: =VLOOKUP(A22,'BASE '!$B$2:$AH$87,33,FALSE) -> 523973.89 | E22: =D22-C22 -> -1422696.1 | F22: =D22/C22 -> 0.26916421
A23: 50 | B23: TARHIL 2 | C23: 1140282 | D23: =VLOOKUP(A23,'BASE '!$B$2:$AH$87,33,FALSE) -> 272436.09 | E23: =D23-C23 -> -867845.91 | F23: =D23/C23 -> 0.23891993
A24: 42 | B24: CARREFOUR 2 | C24: 2325840 | D24: =VLOOKUP(A24,'BASE '!$B$2:$AH$87,33,FALSE) -> 536080.4 | E24: =D24-C24 -> -1789759.6 | F24: =D24/C24 -> 0.23048894
A25: 51 | B25: TARHIL 3 | C25: 1182654 | D25: =VLOOKUP(A25,'BASE '!$B$2:$AH$87,33,FALSE) -> 268593.59 | E25: =D25-C25 -> -914060.41 | F25: =D25/C25 -> 0.22711088
A26: 49 | B26: TARHIL 1 | C26: 1905090 | D26: =VLOOKUP(A26,'BASE '!$B$2:$AH$87,33,FALSE) -> 419997.1 | E26: =D26-C26 -> -1485092.9 | F26: =D26/C26 -> 0.2204605
A27: 90 | B27: ARAFAT | C27: 3300000 | D27: =VLOOKUP(A27,'BASE '!$B$2:$AH$87,33,FALSE) -> 610061.38 | E27: =D27-C27 -> -2689938.6 | F27: =D27/C27 -> 0.18486708
A28: 45 | B28: MELLAH 1 | C28: 2530000 | D28: =VLOOKUP(A28,'BASE '!$B$2:$AH$87,33,FALSE) -> 430622.99 | E28: =D28-C28 -> -2099377 | F28: =D28/C28 -> 0.17020672
A29: 46 | B29: MELLAH 2 | C29: 2038168 | D29: =VLOOKUP(A29,'BASE '!$B$2:$AH$87,33,FALSE) -> 335529.79 | E29: =D29-C29 -> -1702638.2 | F29: =D29/C29 -> 0.16462323
A30: 94 | B30: EL MINA | C30: 6136680 | D30: =VLOOKUP(A30,'BASE '!$B$2:$AH$87,33,FALSE) -> 556738.19 | E30: =D30-C30 -> -5579941.8 | F30: =D30/C30 -> 0.090723028
A31: TOTAL ZONE NKTT SUD | C31: =SUM(C20:C30) -> 27475342 | D31: =SUM(D20:D30) -> 5677396.6 | E31: =SUM(E20:E30) -> -21797946 | F31: =D31/C31 -> 0.20663606
A33: ZONE NKTT OUEST
A34: EXP | B34: CENTRE | C34: OBJECTIF DC | D34: ='BASE '!P92 -> ENCAISSEMENTS AU 12/04/2026 | E34: ECART DU MOIS | F34: %
A35: 55 | B35: TVZ NORD 3 | C35: 4480630 | D35: =VLOOKUP(A35,'BASE '!$B$2:$AH$87,33,FALSE) -> 2145647.4 | E35: =D35-C35 -> -2334982.6 | F35: =D35/C35 -> 0.47887181
A36: 43 | B36: TVZ SUD | C36: 5518590 | D36: =VLOOKUP(A36,'BASE '!$B$2:$AH$87,33,FALSE) -> 1397501.7 | E36: =D36-C36 -> -4121088.3 | F36: =D36/C36 -> 0.25323528
A37: 97 | B37: TVZ NORD 2 | C37: 7154840 | D37: =VLOOKUP(A37,'BASE '!$B$2:$AH$87,33,FALSE) -> 1621240.5 | E37: =D37-C37 -> -5533599.5 | F37: =D37/C37 -> 0.22659353
A38: 93 | B38: SEBKHA | C38: 2402400 | D38: =VLOOKUP(A38,'BASE '!$B$2:$AH$87,33,FALSE) -> 518901.79 | E38: =D38-C38 -> -1883498.2 | F38: =D38/C38 -> 0.21599309
A39: 91 | B39: TVZ NORD 1 | C39: 8800000 | D39: =VLOOKUP(A39,'BASE '!$B$2:$AH$87,33,FALSE) -> 2474469.6 | E39: =D39-C39 -> -6325530.4 | F39: =D39/C39 -> 0.28118972
A40: 92 | B40: CAPITALE | C40: 7150000 | D40: =VLOOKUP(A40,'BASE '!$B$2:$AH$87,33,FALSE) -> 914023.89 | E40: =D40-C40 -> -6235976.1 | F40: =D40/C40 -> 0.12783551
A41: TOTAL ZONE NKTT OUEST | C41: =SUM(C35:C40) -> 35506460 | D41: =SUM(D35:D40) -> 9071784.8 | E41: =SUM(E35:E40) -> -26434675 | F41: =D41/C41 -> 0.25549674
A43: TOTAL NOUAKCHOTT | C43: =C15+C31+C41 -> 85680610 | D43: =D15+D31+D41 -> 20979765 | E43: =E15+E31+E41 -> -64700845 | F43: =D43/C43 -> 0.24486012
...

Sheet COMPARAISON
A1: SNDE
A2: DG
A3: COMPARAISON DES ENCAISSEMENTS GLOBAUX ENTRE AVRIL 2026 ET DECMBRE 2025
A5: NOUALKCHOTT | B5: EXP | C5: CENTRE | D5: ='BASE '!P92 -> ENCAISSEMENTS AU 12/04/2026 | M5: ='MOIS COMP'!I92 -> ENCAISSEMENTS AU 12/12/2025 | O5: ECART
A6: ZONE NKTT NORD | B6: 41 | C6: TEYARETT 2 | D6: =VLOOKUP(B6,'BASE '!B7:AH92,33,FALSE) -> 1049827.6 | M6: =VLOOKUP(B6,'MOIS COMP'!A8:AG93,33,FALSE) -> 948869.6 | O6: =D6-M6 -> 100957.99
A7: ZONE NKTT NORD | B7: 47 | C7: TEYARETT 1 | D7: =VLOOKUP(B7,'BASE '!B4:AH89,33,FALSE) -> 789965.59 | M7: =VLOOKUP(B7,'MOIS COMP'!A5:AG90,33,FALSE) -> 770898.69 | O7: =D7-M7 -> 19066.899
A8: ZONE NKTT NORD | B8: 99 | C8: DAR NAIM-SUD 1 | D8: =VLOOKUP(B8,'BASE '!B6:AH91,33,FALSE) -> 512338.89 | M8: =VLOOKUP(B8,'MOIS COMP'!A7:AG92,33,FALSE) -> 552088.79 | O8: =D8-M8 -> -39749.9
A9: ZONE NKTT NORD | B9: 52 | C9: MELLAH 3 | D9: =VLOOKUP(B9,'BASE '!B8:AH93,33,FALSE) -> 447698.69 | M9: =VLOOKUP(B9,'MOIS COMP'!A9:AG94,33,FALSE) -> 551691.47 | O9: =D9-M9 -> -103992.78
A10: ZONE NKTT NORD | B10: 44 | C10: DAR NAIM-NORD | D10: =VLOOKUP(B10,'BASE '!B10:AH95,33,FALSE) -> 424042.3 | M10: =VLOOKUP(B10,'MOIS COMP'!A11:AG96,33,FALSE) -> 607495.25 | O10: =D10-M10 -> -183452.95
A11: ZONE NKTT NORD | B11: 48 | C11: DAR NAIM-SUD 2 | D11: =VLOOKUP(B11,'BASE '!B5:AH90,33,FALSE) -> 468417.5 | M11: =VLOOKUP(B11,'MOIS COMP'!A6:AG91,33,FALSE) -> 686004.38 | O11: =D11-M11 -> -217586.88
A12: ZONE NKTT NORD | B12: 86 | C12: WAD NAGA | D12: =VLOOKUP(B12,'BASE '!B9:AH94,33,FALSE) -> 583133.1 | M12: =VLOOKUP(B12,'MOIS COMP'!A10:AG95,33,FALSE) -> 856728.39 | O12: =D12-M12 -> -273595.29
A13: ZONE NKTT NORD | B13: 96 | C13: KSAR | D13: =VLOOKUP(B13,'BASE '!B2:AH87,33,FALSE) -> 1460235.9 | M13: =VLOOKUP(B13,'MOIS COMP'!A3:AG87,33,FALSE) -> 1734260.1 | O13: =D13-M13 -> -274024.21
A14: ZONE NKTT NORD | B14: 98 | C14: TOUJOUNINE | D14: =VLOOKUP(B14,'BASE '!B3:AH88,33,FALSE) -> 494924.01 | M14: =VLOOKUP(B14,'MOIS COMP'!A4:AG89,33,FALSE) -> 1132812 | O14: =D14-M14 -> -637887.98
A15: TOTAL ZONE NKTT NORD | D15: =SUM(D6:D14) -> 6230583.5 | M15: =SUM(M6:M14) -> 7840848.6 | O15: =D15-M15 -> -1610265.1
A17: ZONE NKTT OUEST | B17: 55 | C17: TVZ NORD 3 | D17: =VLOOKUP(B17,'BASE '!$B$13:$AH$98,33,FALSE) -> 2145647.4 | M17: =VLOOKUP(B17,'MOIS COMP'!$A$14:$AG$99,33,FALSE) -> 1834078.7 | O17: =D17-M17 -> 311568.7
A18: ZONE NKTT OUEST | B18: 97 | C18: TVZ NORD 2 | D18: =VLOOKUP(B18,'BASE '!$B$13:$AH$98,33,FALSE) -> 1621240.5 | M18: =VLOOKUP(B18,'MOIS COMP'!$A$14:$AG$99,33,FALSE) -> 1486617.6 | O18: =D18-M18 -> 134622.87
A19: ZONE NKTT OUEST | B19: 93 | C19: SEBKHA | D19: =VLOOKUP(B19,'BASE '!$B$13:$AH$98,33,FALSE) -> 518901.79 | M19: =VLOOKUP(B19,'MOIS COMP'!$A$14:$AG$99,33,FALSE) -> 787606.76 | O19: =D19-M19 -> -268704.97
A20: ZONE NKTT OUEST | B20: 43 | C20: TVZ SUD | D20: =VLOOKUP(B20,'BASE '!$B$13:$AH$98,33,FALSE) -> 1397501.7 | M20: =VLOOKUP(B20,'MOIS COMP'!$A$14:$AG$99,33,FALSE) -> 1696097.8 | O20: =D20-M20 -> -298596.08
A21: ZONE NKTT OUEST | B21: 91 | C21: TVZ NORD 1 | D21: =VLOOKUP(B21,'BASE '!$B$13:$AH$98,33,FALSE) -> 2474469.6 | M21: =VLOOKUP(B21,'MOIS COMP'!$A$14:$AG$99,33,FALSE) -> 3394633.8 | O21: =D21-M21 -> -920164.19
A22: ZONE NKTT OUEST | B22: 92 | C22: CAPITALE | D22: =VLOOKUP(B22,'BASE '!$B$13:$AH$98,33,FALSE) -> 914023.89 | M22: =VLOOKUP(B22,'MOIS COMP'!$A$14:$AG$99,33,FALSE) -> 1895276.5 | O22: =D22-M22 -> -981252.59
A23: TOTAL ZONE NKTT OUEST | D23: =SUM(D17:D22) -> 9071784.8 | E23: =SUM(E17:E22) -> 0 | F23: =SUM(F17:F22) -> 0 | G23: =SUM(G17:G22) -> 0 | H23: =SUM(H17:H22) -> 0 | I23: =SUM(I17:I22) -> 0 | J23: =SUM(J17:J22) -> 0 | K23: =SUM(K17:K22) -> 0 | M23: =SUM(M17:M22) -> 11094311 | O23: =SUM(O17:O22) -> -2022526.3
A25: ZONE NKTT SUD | B25: 51 | C25: TARHIL 3 | D25: =VLOOKUP(B25,'BASE '!$B$21:$AH$106,33,FALSE) -> 268593.59 | M25: =VLOOKUP(B25,'MOIS COMP'!$A$14:$AG$99,33,FALSE) -> 147393.19 | O25: =D25-M25 -> 121200.4
A26: ZONE NKTT SUD | B26: 95 | C26: CARREFOUR | D26: =VLOOKUP(B26,'BASE '!$B$21:$AH$106,33,FALSE) -> 982564.6 | M26: =VLOOKUP(B26,'MOIS COMP'!$A$14:$AG$99,33,FALSE) -> 911394.28 | O26: =D26-M26 -> 71170.32
A27: ZONE NKTT SUD | B27: 89 | C27: RIYAD | D27: =VLOOKUP(B27,'BASE '!$B$21:$AH$106,33,FALSE) -> 740798.56 | M27: =VLOOKUP(B27,'MOIS COMP'!$A$14:$AG$99,33,FALSE) -> 734589.98 | O27: =D27-M27 -> 6208.581
A28: ZONE NKTT SUD | B28: 53 | C28: RIYADH 2 | D28: =VLOOKUP(B28,'BASE '!$B$21:$AH$106,33,FALSE) -> 523973.89 | M28: =VLOOKUP(B28,'MOIS COMP'!$A$14:$AG$99,33,FALSE) -> 541735.96 | O28: =D28-M28 -> -17762.07
A29: ZONE NKTT SUD | B29: 49 | C29: TARHIL 1 | D29: =VLOOKUP(B29,'BASE '!$B$21:$AH$106,33,FALSE) -> 419997.1 | M29: =VLOOKUP(B29,'MOIS COMP'!$A$14:$AG$99,33,FALSE) -> 510471.85 | O29: =D29-M29 -> -90474.75
A30: ZONE NKTT SUD | B30: 42 | C30: CARREFOUR 2 | D30: =VLOOKUP(B30,'BASE '!$B$21:$AH$106,33,FALSE) -> 536080.4 | M30: =VLOOKUP(B30,'MOIS COMP'!$A$14:$AG$99,33,FALSE) -> 628248.99 | O30: =D30-M30 -> -92168.59
A31: ZONE NKTT SUD | B31: 50 | C31: TARHIL 2 | D31: =VLOOKUP(B31,'BASE '!$B$21:$AH$106,33,FALSE) -> 272436.09 | M31: =VLOOKUP(B31,'MOIS COMP'!$A$14:$AG$99,33,FALSE) -> 422490.69 | O31: =D31-M31 -> -150054.6
A32: ZONE NKTT SUD | B32: 46 | C32: MELLAH 2 | D32: =VLOOKUP(B32,'BASE '!$B$21:$AH$106,33,FALSE) -> 335529.79 | M32: =VLOOKUP(B32,'MOIS COMP'!$A$14:$AG$99,33,FALSE) -> 516466.85 | O32: =D32-M32 -> -180937.06
A33: ZONE NKTT SUD | B33: 90 | C33: ARAFAT | D33: =VLOOKUP(B33,'BASE '!$B$21:$AH$106,33,FALSE) -> 610061.38 | M33: =VLOOKUP(B33,'MOIS COMP'!$A$14:$AG$99,33,FALSE) -> 882597.49 | O33: =D33-M33 -> -272536.11
A34: ZONE NKTT SUD | B34: 45 | C34: MELLAH 1 | D34: =VLOOKUP(B34,'BASE '!$B$21:$AH$106,33,FALSE) -> 430622.99 | M34: =VLOOKUP(B34,'MOIS COMP'!$A$14:$AG$99,33,FALSE) -> 709856.1 | O34: =D34-M34 -> -279233.11
A35: ZONE NKTT SUD | B35: 94 | C35: EL MINA | D35: =VLOOKUP(B35,'BASE '!$B$21:$AH$106,33,FALSE) -> 556738.19 | E35: =VLOOKUP(C35,[1]Feuil5!$B$4:$V$88,21,FALSE) -> #N/A | F35: =VLOOKUP(D35,[1]Feuil5!$B$4:$V$88,21,FALSE) -> #N/A | G35: =VLOOKUP(E35,[1]Feuil5!$B$4:$V$88,21,FALSE) -> #N/A | H35: =VLOOKUP(F35,[1]Feuil5!$B$4:$V$88,21,FALSE) -> #N/A | I35: =VLOOKUP(G35,[1]Feuil5!$B$4:$V$88,21,FALSE) -> #N/A | J35: =VLOOKUP(H35,[1]Feuil5!$B$4:$V$88,21,FALSE) -> #N/A | K35: =VLOOKUP(I35,[1]Feuil5!$B$4:$V$88,21,FALSE) -> #N/A | M35: =VLOOKUP(B35,'MOIS COMP'!$A$14:$AG$99,33,FALSE) -> 902480.79 | O35: =D35-M35 -> -345742.6
A36: TOTAL ZONE SUD | D36: =SUM(D25:D35) -> 5677396.6 | E36: =SUM(E25:E35) -> #N/A | F36: =SUM(F25:F35) -> #N/A | G36: =SUM(G25:G35) -> #N/A | H36: =SUM(H25:H35) -> #N/A | I36: =SUM(I25:I35) -> #N/A | J36: =SUM(J25:J35) -> #N/A | K36: =SUM(K25:K35) -> #N/A | M36: =SUM(M25:M35) -> 6907726.2 | O36: =SUM(O25:O35) -> -1230329.6
A38: TOTAL ZONES NKTT | D38: =D15+D23+D36 -> 20979765 | E38: =E15+E23+E36 -> #N/A | F38: =F15+F23+F36 -> #N/A | G38: =G15+G23+G36 -> #N/A | H38: =H15+H23+H36 -> #N/A | I38: =I15+I23+I36 -> #N/A | J38: =J15+J23+J36 -> #N/A | K38: =K15+K23+K36 -> #N/A | M38: =M15+M23+M36 -> 25842886 | O38: =D38-M38 -> -4863120.9
A41: NOUADHIBOU | B41: EXP | C41: CENTRE | D41: =D5 -> ENCAISSEMENTS AU 12/04/2026 | M41: ='MOIS COMP'!I92 -> ENCAISSEMENTS AU 12/12/2025 | O41: ECART
A42: ZONE NDB | B42: 60 | C42: NOUADHIBOU 1 | D42: =VLOOKUP(B42,'BASE '!B4:AH89,33,FALSE) -> 895118.23 | M42: =VLOOKUP(B42,'MOIS COMP'!A5:AG90,33,FALSE) -> 803606.76 | O42: =D42-M42 -> 91511.47
A43: ZONE NDB | B43: 40 | C43: NOUADHIBOU 3 | D43: =VLOOKUP(B43,'BASE '!B3:AH88,33,FALSE) -> 572432.86 | M43: =VLOOKUP(B43,'MOIS COMP'!A4:AG89,33,FALSE) -> 566910.6 | O43: =D43-M43 -> 5522.26
A44: ZONE NDB | B44: 15 | C44: CHAMI | D44: =VLOOKUP(B44,'BASE '!B2:AH87,33,FALSE) -> 7309 | E44: =VLOOKUP(C44,'BASE '!C2:AI87,33,FALSE) -> #N/A | F44: =VLOOKUP(D44,'BASE '!D2:AJ87,33,FALSE) -> #N/A | G44: =VLOOKUP(E44,'BASE '!E2:AK87,33,FALSE) -> #N/A | H44: =VLOOKUP(F44,'BASE '!F2:AL87,33,FALSE) -> #N/A | I44: =VLOOKUP(G44,'BASE '!G2:AM87,33,FALSE) -> #N/A | J44: =VLOOKUP(H44,'BASE '!H2:AN87,33,FALSE) -> #N/A | K44: =VLOOKUP(I44,'BASE '!I2:AO87,33,FALSE) -> #N/A | M44: =VLOOKUP(B44,'MOIS COMP'!A3:AG87,33,FALSE) -> 40507.4 | O44: =D44-M44 -> -33198.4
A45: ZONE NDB | B45: 80 | C45: NOUADHIBOU 2 | D45: =VLOOKUP(B45,'BASE '!B38:AH123,33,FALSE) -> 920851.79 | E45: =VLOOKUP(C45,'BASE '!$B$38:$AH$123,33,FALSE) -> #N/A | F45: =VLOOKUP(D45,'BASE '!$B$38:$AH$123,33,FALSE) -> #N/A | G45: =VLOOKUP(E45,'BASE '!$B$38:$AH$123,33,FALSE) -> #N/A | H45: =VLOOKUP(F45,'BASE '!$B$38:$AH$123,33,FALSE) -> #N/A | I45: =VLOOKUP(G45,'BASE '!$B$38:$AH$123,33,FALSE) -> #N/A | J45: =VLOOKUP(H45,'BASE '!$B$38:$AH$123,33,FALSE) -> #N/A | K45: =VLOOKUP(I45,'BASE '!$B$38:$AH$123,33,FALSE) -> #N/A | M45: =VLOOKUP(B45,'MOIS COMP'!$A$14:$AG$99,33,FALSE) -> 1239212.5 | O45: =D45-M45 -> -318360.67
A46: TOTAL ZONE NDB | D46: =SUM(D42:D45) -> 2395711.9 | M46: =SUM(M42:M45) -> 2650237.2 | O46: =D46-M46 -> -254525.34
...

Sheet NKTT
A1: SNDE
A2: DG
A3: SUIVI OBJECTIFS EN ENCAISSEMENTS GLOBAUX
F4: ='BASE '!P92 -> ENCAISSEMENTS AU 12/04/2026
A5: ZONE | B5: EXP | C5: CENTRE | D5: OBJECTIF DG | E5: OBJECTIF DC | F5: Encaissement Cumulé | G5: ECART DU MOIS | H5: %
A6: NORD | B6: 41 | C6: TEYARETT 2 | D6: 3500000 | E6: 2530000 | F6: =VLOOKUP(B6,'BASE '!$B$2:$AH$87,33,FALSE) -> 1049827.6 | G6: =F6-E6 -> -1480172.4 | H6: =F6/E6 -> 0.41495162
A7: NORD | B7: 44 | C7: DAR NAIM-NORD | D7: 2000000 | E7: 1650000 | F7: =VLOOKUP(B7,'BASE '!$B$2:$AH$87,33,FALSE) -> 424042.3 | G7: =F7-E7 -> -1225957.7 | H7: =F7/E7 -> 0.25699533
A8: NORD | B8: 48 | C8: DAR NAIM-SUD 2 | D8: 2500000 | E8: 2527668 | F8: =VLOOKUP(B8,'BASE '!$B$2:$AH$87,33,FALSE) -> 468417.5 | G8: =F8-E8 -> -2059250.5 | H8: =F8/E8 -> 0.18531607
A9: NORD | B9: 86 | C9: WAD NAGA | D9: 2500000 | E9: 1561340 | F9: =VLOOKUP(B9,'BASE '!$B$2:$AH$87,33,FALSE) -> 583133.1 | G9: =F9-E9 -> -978206.9 | H9: =F9/E9 -> 0.37348246
A10: NORD | B10: 47 | C10: TEYARETT 1 | D10: 3500000 | E10: 2530000 | F10: =VLOOKUP(B10,'BASE '!$B$2:$AH$87,33,FALSE) -> 789965.59 | G10: =F10-E10 -> -1740034.4 | H10: =F10/E10 -> 0.31223936
A11: NORD | B11: 98 | C11: TOUJOUNINE | D11: 3700000 | E11: 3300000 | F11: =VLOOKUP(B11,'BASE '!$B$2:$AH$87,33,FALSE) -> 494924.01 | G11: =F11-E11 -> -2805076 | H11: =F11/E11 -> 0.14997697
A12: NORD | B12: 96 | C12: KSAR | D12: 4500000 | E12: 4400000 | F12: =VLOOKUP(B12,'BASE '!$B$2:$AH$87,33,FALSE) -> 1460235.9 | G12: =F12-E12 -> -2939764.1 | H12: =F12/E12 -> 0.33187179
A13: NORD | B13: 52 | C13: MELLAH 3 | D13: 1800000 | E13: 1810468 | F13: =VLOOKUP(B13,'BASE '!$B$2:$AH$87,33,FALSE) -> 447698.69 | G13: =F13-E13 -> -1362769.3 | H13: =F13/E13 -> 0.2472834
A14: NORD | B14: 99 | C14: DAR NAIM-SUD 1 | D14: 2000000 | E14: 2389332 | F14: =VLOOKUP(B14,'BASE '!$B$2:$AH$87,33,FALSE) -> 512338.89 | G14: =F14-E14 -> -1876993.1 | H14: =F14/E14 -> 0.21442767
A15: OUEST | B15: 91 | C15: TVZ NORD 1 | D15: 9000000 | E15: 8800000 | F15: =VLOOKUP(B15,'BASE '!$B$2:$AH$87,33,FALSE) -> 2474469.6 | G15: =F15-E15 -> -6325530.4 | H15: =F15/E15 -> 0.28118972
A16: OUEST | B16: 55 | C16: TVZ NORD 3 | D16: 7000000 | E16: 4480630 | F16: =VLOOKUP(B16,'BASE '!$B$2:$AH$87,33,FALSE) -> 2145647.4 | G16: =F16-E16 -> -2334982.6 | H16: =F16/E16 -> 0.47887181
A17: OUEST | B17: 97 | C17: TVZ NORD 2 | D17: 6000000 | E17: 7154840 | F17: =VLOOKUP(B17,'BASE '!$B$2:$AH$87,33,FALSE) -> 1621240.5 | G17: =F17-E17 -> -5533599.5 | H17: =F17/E17 -> 0.22659353
... A30: SUD | B30: 51 | C30: TARHIL 3 | D30: 1200000 | E30: 1182654 | F30: =VLOOKUP(B30,'BASE '!$B$2:$AH$87,33,FALSE) -> 268593.59 | G30: =F30-E30 -> -914060.41 | H30: =F30/E30 -> 0.22711088
A31: SUD | B31: 53 | C31: RIYADH 3 | E31: 1946670 | F31: =VLOOKUP(B31,'BASE '!$B$2:$AH$87,33,FALSE) -> 523973.89 | G31: =F31-E31 -> -1422696.1 | H31: =F31/E31 -> 0.26916421
A32: TOTAL NOUAKCHOTT | D32: =SUM(D6:D31) -> 88900000 | E32: =SUM(E6:E31) -> 85680610 | F32: =SUM(F6:F31) -> 20979765 | G32: =D32-F32 -> 67920235 | H32: =F32/E32 -> 0.24486012

Sheet Legende
F1: 1.12
F2: 1.11
F3: 1.1
F4: 1.09
F5: 1.08
F6: 1.07
F7: 1.06
F8: 1.05
F9: 1.04
F10: 1.03
F11: 1.02
F12: 1.01
... F85: 0.28
